<?xml version="1.0"?>
<robot name="hiwonder_jetarm">
  
  <!-- Base Link -->
  <link name="base_link">
    <visual>
      <geometry>
        <cylinder radius="0.05" length="0.06"/>
      </geometry>
      <material name="black">
        <color rgba="0.2 0.2 0.2 1"/>
      </material>
    </visual>
    <collision>
      <geometry>
        <cylinder radius="0.05" length="0.06"/>
      </geometry>
    </collision>
    <inertial>
      <mass value="0.5"/>
      <inertia ixx="0.001" ixy="0" ixz="0" iyy="0.001" iyz="0" izz="0.001"/>
    </inertial>
  </link>

  <!-- Joint 1: Base Rotation -->
  <joint name="joint1" type="revolute">
    <parent link="base_link"/>
    <child link="link1"/>
    <origin xyz="0 0 0.06" rpy="0 0 0"/>
    <axis xyz="0 0 1"/>
    <limit lower="-3.14159" upper="3.14159" effort="10" velocity="1.0"/>
  </joint>

  <link name="link1">
    <visual>
      <geometry>
        <box size="0.04 0.04 0.06"/>
      </geometry>
      <material name="black">
        <color rgba="0.1 0.1 0.1 1"/>
      </material>
    </visual>
    <collision>
      <geometry>
        <box size="0.04 0.04 0.06"/>
      </geometry>
    </collision>
    <inertial>
      <mass value="0.3"/>
      <inertia ixx="0.0001" ixy="0" ixz="0" iyy="0.0001" iyz="0" izz="0.0001"/>
    </inertial>
  </link>

  <!-- Joint 2: Shoulder -->
  <joint name="joint2" type="revolute">
    <parent link="link1"/>
    <child link="link2"/>
    <origin xyz="0 0 0.06" rpy="0 0 0"/>
    <axis xyz="0 1 0"/>
    <limit lower="-1.57079" upper="1.57079" effort="10" velocity="1.0"/>
  </joint>

  <link name="link2">
    <visual>
      <origin xyz="0.044 0 0" rpy="0 0 0"/>
      <geometry>
        <box size="0.088 0.03 0.03"/>
      </geometry>
      <material name="black">
        <color rgba="0.1 0.1 0.1 1"/>
      </material>
    </visual>
    <collision>
      <origin xyz="0.044 0 0" rpy="0 0 0"/>
      <geometry>
        <box size="0.088 0.03 0.03"/>
      </geometry>
    </collision>
    <inertial>
      <mass value="0.2"/>
      <inertia ixx="0.0001" ixy="0" ixz="0" iyy="0.0001" iyz="0" izz="0.0001"/>
    </inertial>
  </link>

  <!-- Joint 3: Elbow -->
  <joint name="joint3" type="revolute">
    <parent link="link2"/>
    <child link="link3"/>
    <origin xyz="0.088 0 0" rpy="0 0 0"/>
    <axis xyz="0 1 0"/>
    <limit lower="-1.57079" upper="1.57079" effort="10" velocity="1.0"/>
  </joint>

  <link name="link3">
    <visual>
      <origin xyz="0.044 0 0" rpy="0 0 0"/>
      <geometry>
        <box size="0.088 0.025 0.025"/>
      </geometry>
      <material name="black">
        <color rgba="0.1 0.1 0.1 1"/>
      </material>
    </visual>
    <collision>
      <origin xyz="0.044 0 0" rpy="0 0 0"/>
      <geometry>
        <box size="0.088 0.025 0.025"/>
      </geometry>
    </collision>
    <inertial>
      <mass value="0.15"/>
      <inertia ixx="0.0001" ixy="0" ixz="0" iyy="0.0001" iyz="0" izz="0.0001"/>
    </inertial>
  </link>

  <!-- Joint 4: Wrist Rotation -->
  <joint name="joint4" type="revolute">
    <parent link="link3"/>
    <child link="link4"/>
    <origin xyz="0.088 0 0" rpy="0 0 0"/>
    <axis xyz="1 0 0"/>
    <limit lower="-1.57079" upper="1.57079" effort="5" velocity="1.0"/>
  </joint>

  <link name="link4">
    <visual>
      <geometry>
        <cylinder radius="0.015" length="0.06"/>
      </geometry>
      <material name="black">
        <color rgba="0.1 0.1 0.1 1"/>
      </material>
    </visual>
    <collision>
      <geometry>
        <cylinder radius="0.015" length="0.06"/>
      </geometry>
    </collision>
    <inertial>
      <mass value="0.1"/>
      <inertia ixx="0.00001" ixy="0" ixz="0" iyy="0.00001" iyz="0" izz="0.00001"/>
    </inertial>
  </link>

  <!-- Joint 5: Wrist Pitch -->
  <joint name="joint5" type="revolute">
    <parent link="link4"/>
    <child link="link5"/>
    <origin xyz="0 0 0.06" rpy="0 0 0"/>
    <axis xyz="0 1 0"/>
    <limit lower="-1.57079" upper="1.57079" effort="5" velocity="1.0"/>
  </joint>

  <link name="link5">
    <visual>
      <origin xyz="0.03 0 0" rpy="0 0 0"/>
      <geometry>
        <box size="0.06 0.02 0.02"/>
      </geometry>
      <material name="black">
        <color rgba="0.1 0.1 0.1 1"/>
      </material>
    </visual>
    <collision>
      <origin xyz="0.03 0 0" rpy="0 0 0"/>
      <geometry>
        <box size="0.06 0.02 0.02"/>
      </geometry>
    </collision>
    <inertial>
      <mass value="0.08"/>
      <inertia ixx="0.00001" ixy="0" ixz="0" iyy="0.00001" iyz="0" izz="0.00001"/>
    </inertial>
  </link>

  <!-- Joint 6: Gripper (simplified as revolute) -->
  <joint name="joint6" type="revolute">
    <parent link="link5"/>
    <child link="gripper"/>
    <origin xyz="0.06 0 0" rpy="0 0 0"/>
    <axis xyz="0 0 1"/>
    <limit lower="-0.785398" upper="0.785398" effort="2" velocity="0.5"/>
  </joint>

  <link name="gripper">
    <visual>
      <geometry>
        <box size="0.02 0.03 0.01"/>
      </geometry>
      <material name="black">
        <color rgba="0.1 0.1 0.1 1"/>
      </material>
    </visual>
    <collision>
      <geometry>
        <box size="0.02 0.03 0.01"/>
      </geometry>
    </collision>
    <inertial>
      <mass value="0.05"/>
      <inertia ixx="0.00001" ixy="0" ixz="0" iyy="0.00001" iyz="0" izz="0.00001"/>
    </inertial>
  </link>

</robot>
